In Celery, a **group task**  is a collection of tasks that execute in parallel, and their results are aggregated. When working with **Celery group tasks in Django** , handling errors properly is crucial to ensure that failures do not break the entire workflow.

---

ðŸš€ **Error Handling in Celery Group Tasks**
Celery provides different mechanisms to handle errors in a group:

1. **Using `group().apply_async()` with `link_error`**

- This allows you to specify an error callback that will be executed if any task in the group fails.

```python
from celery import group
from myapp.tasks import process_data, handle_error

result = group(
    process_data.s(1),
    process_data.s(2),
    process_data.s(3)
).apply_async(link_error=handle_error.s())
```

Here, `handle_error.s()` will be executed if any task in the group fails.

2. **Handling Errors Individually with `on_error` in Task Decorators**  

- You can define error handling within each task using `on_failure()`.

```python
from celery import Task

class CustomTask(Task):
    def on_failure(self, exc, task_id, args, kwargs, einfo):
        print(f'Task {task_id} failed: {exc}')

@app.task(base=CustomTask)
def process_data(x):
    if x == 2:
        raise ValueError("Simulated Failure")
    return x * 10
```

3. **Using `chord()` for Error Handling**  

- `chord()` is like `group()` but allows you to define a callback that runs after all tasks complete.

- If any task in the group fails, the callback is **not**  executed by default. You can handle this by setting `chord_error`.

```python
from celery import chord
from myapp.tasks import process_data, final_callback, handle_error

result = chord(
    (process_data.s(x) for x in range(5)),
    final_callback.s()
).apply_async()

result.on_error(handle_error.s())
```

- `handle_error.s()` will be called if **any**  task fails.

4. **Using `ResultSet` to Check for Failures**

- You can manually iterate over results and check for failures.

```python
from celery import group

result = group(
    process_data.s(1),
    process_data.s(2),
    process_data.s(3)
).apply_async()

for res in result.children:
    if res.failed():
        print(f'Task {res.id} failed with error: {res.result}')
```

---

âœ… **Best Practices for Error Handling in Celery Group Tasks**  

1. **Use Retries**  â€“ If tasks are failing due to transient issues, use `autoretry_for`:

```python
from celery import shared_task
from celery.exceptions import MaxRetriesExceededError

@shared_task(bind=True, autoretry_for=(Exception,), retry_backoff=5, max_retries=3)
def process_data(self, x):
    try:
        # Simulate processing
        if x == 2:
            raise ValueError("Random failure")
        return x * 10
    except Exception as e:
        raise self.retry(exc=e)
```

2. **Use Dedicated Error Callbacks**  â€“ `link_error` helps separate logic from error handling.

3. **Store Errors in Logs or Database**  â€“ You can log errors in Django models or logs for debugging.

4. **Use `ignore_result=True` for Non-Critical Tasks**  â€“ If the result isnâ€™t needed, avoid cluttering the result backend.

---
