Error handling in Celery chain tasks with Django is crucial because if one task in the chain fails, the entire chain stops unless explicitly handled. Let’s break it down:

### 🔹 What is a Celery Chain?

A **Celery chain**  is a sequence of tasks that execute one after another, where the output of one task becomes the input of the next.
Example:

```python
from celery import chain
from myapp.tasks import task_a, task_b, task_c

workflow = chain(task_a.s(10) | task_b.s() | task_c.s())
workflow.apply_async()
```

If `task_a` fails, `task_b` and `task_c` will not run.

---

## 🔥 Error Handling Strategies in Celery Chain

1️⃣ Using `on_error` Callbacks**
You can define an error callback that runs when a task in the chain fails.

```python
from celery import chain
from myapp.tasks import task_a, task_b, task_c, error_handler

workflow = chain(
    task_a.s(10).on_error(error_handler.s()),
    task_b.s(),
    task_c.s()
)
workflow.apply_async()
```

📌 **How it Works?**  

- If `task_a` fails, `error_handler` runs.

- The chain stops unless error handling re-triggers it.

---

2️⃣ **Handling Errors Inside Tasks**
Modify each task to handle failures and continue the chain.

```python
from celery import shared_task

@shared_task(bind=True)
def task_a(self, x):
    try:
        return x / 0  # This will cause an error
    except Exception as e:
        return {"error": str(e)}  # Prevents chain from breaking

@shared_task
def task_b(data):
    if "error" in data:
        return f"Skipping task_b due to error: {data['error']}"
    return data * 2
```

📌 **How it Works?**

- Instead of raising an error, the task returns a message.

- `task_b` checks for errors before proceeding.

---

3️⃣ Using `link_error` for Global Error Handling**
If any task in the chain fails, a separate task can handle the failure.

```python
from celery import chain
from myapp.tasks import task_a, task_b, task_c, error_handler

workflow = chain(task_a.s(10), task_b.s(), task_c.s()).apply_async(link_error=error_handler.s())
```

📌 **How it Works?**  

- If any task fails, `error_handler` runs separately.

- The chain still stops on failure.

---

4️⃣ Using `celery.chord` for Partial Recovery** If you need to continue even after a failure, use `chord`.

```python
from celery import chord
from myapp.tasks import task_a, task_b, task_c, final_task

workflow = chord([task_a.s(10), task_b.s()], final_task.s())
workflow.apply_async()
```

📌 **How it Works?**  

- `task_a` and `task_b` run in parallel.

- If one fails, the final task still executes.

---

## ✅ Best Practice Recommendation

- **Use `on_error` for per-task error handling.**

- **Use `link_error` for global error handling.**

- **Use `try/except` inside tasks if you want partial recovery.**

- **Use `chord` if you need a final task to run even if some fail.**
